INFO  [alembic.runtime.migration] Context impl SQLiteImpl.
INFO  [alembic.runtime.migration] Will assume non-transactional DDL.
INFO  [alembic.runtime.migration] Running upgrade  -> 6664325c78de, Add Team model and team_id to User
Traceback (most recent call last):
  File "/home/naba/DAT/venv/lib/python3.6/site-packages/sqlalchemy/engine/base.py", line 1911, in _execute_context
    cursor, statement, parameters, context
  File "/home/naba/DAT/venv/lib/python3.6/site-packages/sqlalchemy/engine/default.py", line 736, in do_execute
    cursor.execute(statement, parameters)
sqlite3.OperationalError: table team already exists

The above exception was the direct cause of the following exception:

Traceback (most recent call last):
  File "/home/naba/DAT/venv/bin/flask", line 11, in <module>
    sys.exit(main())
  File "/home/naba/DAT/venv/lib/python3.6/site-packages/flask/cli.py", line 995, in main
    cli.main(args=sys.argv[1:])
  File "/home/naba/DAT/venv/lib/python3.6/site-packages/flask/cli.py", line 601, in main
    return super().main(*args, **kwargs)
  File "/home/naba/DAT/venv/lib/python3.6/site-packages/click/core.py", line 1053, in main
    rv = self.invoke(ctx)
  File "/home/naba/DAT/venv/lib/python3.6/site-packages/click/core.py", line 1659, in invoke
    return _process_result(sub_ctx.command.invoke(sub_ctx))
  File "/home/naba/DAT/venv/lib/python3.6/site-packages/click/core.py", line 1659, in invoke
    return _process_result(sub_ctx.command.invoke(sub_ctx))
  File "/home/naba/DAT/venv/lib/python3.6/site-packages/click/core.py", line 1395, in invoke
    return ctx.invoke(self.callback, **ctx.params)
  File "/home/naba/DAT/venv/lib/python3.6/site-packages/click/core.py", line 754, in invoke
    return __callback(*args, **kwargs)
  File "/home/naba/DAT/venv/lib/python3.6/site-packages/click/decorators.py", line 26, in new_func
    return f(get_current_context(), *args, **kwargs)
  File "/home/naba/DAT/venv/lib/python3.6/site-packages/flask/cli.py", line 445, in decorator
    return __ctx.invoke(f, *args, **kwargs)
  File "/home/naba/DAT/venv/lib/python3.6/site-packages/click/core.py", line 754, in invoke
    return __callback(*args, **kwargs)
  File "/home/naba/DAT/venv/lib/python3.6/site-packages/flask_migrate/cli.py", line 149, in upgrade
    _upgrade(directory, revision, sql, tag, x_arg)
  File "/home/naba/DAT/venv/lib/python3.6/site-packages/flask_migrate/__init__.py", line 111, in wrapped
    f(*args, **kwargs)
  File "/home/naba/DAT/venv/lib/python3.6/site-packages/flask_migrate/__init__.py", line 200, in upgrade
    command.upgrade(config, revision, sql=sql, tag=tag)
  File "/home/naba/DAT/venv/lib/python3.6/site-packages/alembic/command.py", line 320, in upgrade
    script.run_env()
  File "/home/naba/DAT/venv/lib/python3.6/site-packages/alembic/script/base.py", line 563, in run_env
    util.load_python_file(self.dir, "env.py")
  File "/home/naba/DAT/venv/lib/python3.6/site-packages/alembic/util/pyfiles.py", line 92, in load_python_file
    module = load_module_py(module_id, path)
  File "/home/naba/DAT/venv/lib/python3.6/site-packages/alembic/util/pyfiles.py", line 108, in load_module_py
    spec.loader.exec_module(module)  # type: ignore
  File "<frozen importlib._bootstrap_external>", line 678, in exec_module
  File "<frozen importlib._bootstrap>", line 219, in _call_with_frames_removed
  File "migrations/env.py", line 105, in <module>
    run_migrations_online()
  File "migrations/env.py", line 99, in run_migrations_online
    context.run_migrations()
  File "<string>", line 8, in run_migrations
  File "/home/naba/DAT/venv/lib/python3.6/site-packages/alembic/runtime/environment.py", line 851, in run_migrations
    self.get_context().run_migrations(**kw)
  File "/home/naba/DAT/venv/lib/python3.6/site-packages/alembic/runtime/migration.py", line 620, in run_migrations
    step.migration_fn(**kw)
  File "/home/naba/DAT/migrations/versions/6664325c78de_add_team_model_and_team_id_to_user.py", line 25, in upgrade
    sa.UniqueConstraint('name')
  File "<string>", line 8, in create_table
  File "<string>", line 3, in create_table
  File "/home/naba/DAT/venv/lib/python3.6/site-packages/alembic/operations/ops.py", line 1254, in create_table
    return operations.invoke(op)
  File "/home/naba/DAT/venv/lib/python3.6/site-packages/alembic/operations/base.py", line 392, in invoke
    return fn(self, operation)
  File "/home/naba/DAT/venv/lib/python3.6/site-packages/alembic/operations/toimpl.py", line 114, in create_table
    operations.impl.create_table(table)
  File "/home/naba/DAT/venv/lib/python3.6/site-packages/alembic/ddl/impl.py", line 352, in create_table
    self._exec(schema.CreateTable(table))
  File "/home/naba/DAT/venv/lib/python3.6/site-packages/alembic/ddl/impl.py", line 193, in _exec
    return conn.execute(construct, multiparams)
  File "/home/naba/DAT/venv/lib/python3.6/site-packages/sqlalchemy/engine/base.py", line 1385, in execute
    return meth(self, multiparams, params, _EMPTY_EXECUTION_OPTS)
  File "/home/naba/DAT/venv/lib/python3.6/site-packages/sqlalchemy/sql/ddl.py", line 81, in _execute_on_connection
    self, multiparams, params, execution_options
  File "/home/naba/DAT/venv/lib/python3.6/site-packages/sqlalchemy/engine/base.py", line 1483, in _execute_ddl
    compiled,
  File "/home/naba/DAT/venv/lib/python3.6/site-packages/sqlalchemy/engine/base.py", line 1954, in _execute_context
    e, statement, parameters, cursor, context
  File "/home/naba/DAT/venv/lib/python3.6/site-packages/sqlalchemy/engine/base.py", line 2135, in _handle_dbapi_exception
    sqlalchemy_exception, with_traceback=exc_info[2], from_=e
  File "/home/naba/DAT/venv/lib/python3.6/site-packages/sqlalchemy/util/compat.py", line 211, in raise_
    raise exception
  File "/home/naba/DAT/venv/lib/python3.6/site-packages/sqlalchemy/engine/base.py", line 1911, in _execute_context
    cursor, statement, parameters, context
  File "/home/naba/DAT/venv/lib/python3.6/site-packages/sqlalchemy/engine/default.py", line 736, in do_execute
    cursor.execute(statement, parameters)
sqlalchemy.exc.OperationalError: (sqlite3.OperationalError) table team already exists
[SQL: 
CREATE TABLE team (
	id INTEGER NOT NULL, 
	name VARCHAR(64) NOT NULL, 
	PRIMARY KEY (id), 
	UNIQUE (name)
)

]
(Background on this error at: https://sqlalche.me/e/14/e3q8)
